[2025-06-29T17:31:49.410+0000] {taskinstance.py:1956} INFO - Dependencies all met for dep_context=non-requeueable deps ti=<TaskInstance: films_dag_orchestaror.dbt_task scheduled__2025-06-29T17:30:00+00:00 [queued]>
[2025-06-29T17:31:49.421+0000] {taskinstance.py:1956} INFO - Dependencies all met for dep_context=requeueable deps ti=<TaskInstance: films_dag_orchestaror.dbt_task scheduled__2025-06-29T17:30:00+00:00 [queued]>
[2025-06-29T17:31:49.421+0000] {taskinstance.py:2170} INFO - Starting attempt 1 of 1
[2025-06-29T17:31:49.437+0000] {taskinstance.py:2191} INFO - Executing <Task(DockerOperator): dbt_task> on 2025-06-29 17:30:00+00:00
[2025-06-29T17:31:49.442+0000] {standard_task_runner.py:60} INFO - Started process 173 to run task
[2025-06-29T17:31:49.447+0000] {standard_task_runner.py:87} INFO - Running: ['airflow', 'tasks', 'run', 'films_dag_orchestaror', 'dbt_task', 'scheduled__2025-06-29T17:30:00+00:00', '--job-id', '1632', '--raw', '--subdir', 'DAGS_FOLDER/orchestrator.py', '--cfg-path', '/tmp/tmpc9nhege6']
[2025-06-29T17:31:49.450+0000] {standard_task_runner.py:88} INFO - Job 1632: Subtask dbt_task
[2025-06-29T17:31:49.517+0000] {task_command.py:423} INFO - Running <TaskInstance: films_dag_orchestaror.dbt_task scheduled__2025-06-29T17:30:00+00:00 [running]> on host c3520c5c5ff0
[2025-06-29T17:31:49.623+0000] {taskinstance.py:2480} INFO - Exporting env vars: AIRFLOW_CTX_DAG_OWNER='airflow' AIRFLOW_CTX_DAG_ID='films_dag_orchestaror' AIRFLOW_CTX_TASK_ID='dbt_task' AIRFLOW_CTX_EXECUTION_DATE='2025-06-29T17:30:00+00:00' AIRFLOW_CTX_TRY_NUMBER='1' AIRFLOW_CTX_DAG_RUN_ID='scheduled__2025-06-29T17:30:00+00:00'
[2025-06-29T17:31:49.664+0000] {docker.py:359} INFO - Starting docker container from image ghcr.io/dbt-labs/dbt-postgres:1.9.latest
[2025-06-29T17:31:49.673+0000] {docker.py:367} WARNING - Using remote engine or docker-in-docker and mounting temporary volume from host is not supported. Falling back to `mount_tmp_dir=False` mode. You can set `mount_tmp_dir` parameter to False to disable mounting and remove the warning
[2025-06-29T17:31:51.797+0000] {docker.py:429} INFO - [0m17:31:51  Running with dbt=1.9.0
[2025-06-29T17:31:52.114+0000] {docker.py:429} INFO - [0m17:31:52  Registered adapter: postgres=1.9.0
[2025-06-29T17:31:52.347+0000] {docker.py:429} INFO - [0m17:31:52  [[33mWARNING[0m]: Configuration paths exist in your dbt_project.yml file which do not apply to any resources.
There are 1 unused configuration paths:
- models.my_dbt_project.example
[2025-06-29T17:31:52.535+0000] {docker.py:429} INFO - [0m17:31:52  Found 3 models, 3 sources, 431 macros
[2025-06-29T17:31:52.539+0000] {docker.py:429} INFO - [0m17:31:52
[2025-06-29T17:31:52.539+0000] {docker.py:429} INFO - [0m17:31:52  Concurrency: 4 threads (target='dev')
[2025-06-29T17:31:52.541+0000] {docker.py:429} INFO - [0m17:31:52
[2025-06-29T17:31:52.695+0000] {docker.py:429} INFO - [0m17:31:52  1 of 3 START sql table model dev.film_rating ................................... [RUN]
[2025-06-29T17:31:52.696+0000] {docker.py:429} INFO - [0m17:31:52  2 of 3 START sql table model dev.staging ....................................... [RUN]
[2025-06-29T17:31:52.951+0000] {docker.py:429} INFO - [0m17:31:52  2 of 3 OK created sql table model dev.staging .................................. [[32mSELECT 31660[0m in 0.25s]
[2025-06-29T17:31:52.954+0000] {docker.py:429} INFO - [0m17:31:52  1 of 3 OK created sql table model dev.film_rating .............................. [[32mSELECT 31660[0m in 0.25s]
[2025-06-29T17:31:52.957+0000] {docker.py:429} INFO - [0m17:31:52  3 of 3 START sql table model dev.film_actors ................................... [RUN]
[2025-06-29T17:38:58.011+0000] {docker.py:429} INFO - [0m17:38:58  3 of 3 ERROR creating sql table model dev.film_actors .......................... [[31mERROR[0m in 425.05s]
[2025-06-29T17:38:58.030+0000] {docker.py:429} INFO - [0m17:38:58
[2025-06-29T17:38:58.031+0000] {docker.py:429} INFO - [0m17:38:58  [33mExited because of keyboard interrupt[0m
[2025-06-29T17:38:58.031+0000] {docker.py:429} INFO - [0m17:38:58
[2025-06-29T17:38:58.032+0000] {docker.py:429} INFO - [0m17:38:58    Database Error in model film_actors (models/staging/film_actors.sql)
  server closed the connection unexpectedly
  	This probably means the server terminated abnormally
  	before or while processing the request.
  compiled code at target/run/my_dbt_project/models/staging/film_actors.sql
[2025-06-29T17:38:58.033+0000] {docker.py:429} INFO - [0m17:38:58
[2025-06-29T17:38:58.034+0000] {docker.py:429} INFO - [0m17:38:58  Done. PASS=2 WARN=0 ERROR=1 SKIP=0 TOTAL=3
[2025-06-29T17:38:58.037+0000] {docker.py:429} INFO - [0m17:38:58
[2025-06-29T17:38:58.037+0000] {docker.py:429} INFO - [0m17:38:58  Finished running 3 table models in 0 hours 7 minutes and 5.50 seconds (425.50s).
[2025-06-29T17:38:58.038+0000] {docker.py:429} INFO - [0m17:38:58  Encountered an error:
Database Error
  connection to server at "destination_postgres" (172.18.0.5), port 5432 failed: FATAL:  the database system is shutting down
[2025-06-29T17:38:59.396+0000] {taskinstance.py:2698} ERROR - Task failed with exception
Traceback (most recent call last):
  File "/home/airflow/.local/lib/python3.10/site-packages/docker/api/client.py", line 265, in _raise_for_status
    response.raise_for_status()
  File "/home/airflow/.local/lib/python3.10/site-packages/requests/models.py", line 1021, in raise_for_status
    raise HTTPError(http_error_msg, response=self)
requests.exceptions.HTTPError: 400 Client Error: Bad Request for url: http+docker://localhost/v1.49/containers/create

The above exception was the direct cause of the following exception:

Traceback (most recent call last):
  File "/home/airflow/.local/lib/python3.10/site-packages/airflow/providers/docker/operators/docker.py", line 364, in _run_image
    return self._run_image_with_mounts([*self.mounts, tmp_mount], add_tmp_variable=True)
  File "/home/airflow/.local/lib/python3.10/site-packages/airflow/providers/docker/operators/docker.py", line 391, in _run_image_with_mounts
    self.container = self.cli.create_container(
  File "/home/airflow/.local/lib/python3.10/site-packages/docker/api/container.py", line 439, in create_container
    return self.create_container_from_config(config, name, platform)
  File "/home/airflow/.local/lib/python3.10/site-packages/docker/api/container.py", line 456, in create_container_from_config
    return self._result(res, True)
  File "/home/airflow/.local/lib/python3.10/site-packages/docker/api/client.py", line 271, in _result
    self._raise_for_status(response)
  File "/home/airflow/.local/lib/python3.10/site-packages/docker/api/client.py", line 267, in _raise_for_status
    raise create_api_error_from_http_exception(e) from e
  File "/home/airflow/.local/lib/python3.10/site-packages/docker/errors.py", line 39, in create_api_error_from_http_exception
    raise cls(e, response=response, explanation=explanation) from e
docker.errors.APIError: 400 Client Error for http+docker://localhost/v1.49/containers/create: Bad Request ("invalid mount config for type "bind": bind source path does not exist: /tmp/airflowtmphkzm3hu_")

During handling of the above exception, another exception occurred:

Traceback (most recent call last):
  File "/home/airflow/.local/lib/python3.10/site-packages/airflow/models/taskinstance.py", line 433, in _execute_task
    result = execute_callable(context=context, **execute_callable_kwargs)
  File "/home/airflow/.local/lib/python3.10/site-packages/airflow/providers/docker/operators/docker.py", line 502, in execute
    return self._run_image()
  File "/home/airflow/.local/lib/python3.10/site-packages/airflow/providers/docker/operators/docker.py", line 373, in _run_image
    return self._run_image_with_mounts(self.mounts, add_tmp_variable=False)
  File "/home/airflow/.local/lib/python3.10/site-packages/airflow/providers/docker/operators/docker.py", line 437, in _run_image_with_mounts
    raise DockerContainerFailedException(f"Docker container failed: {result!r}", logs=log_lines)
airflow.providers.docker.exceptions.DockerContainerFailedException: Docker container failed: {'StatusCode': 2}
[2025-06-29T17:38:59.410+0000] {taskinstance.py:1138} INFO - Marking task as FAILED. dag_id=films_dag_orchestaror, task_id=dbt_task, execution_date=20250629T173000, start_date=20250629T173149, end_date=20250629T173859
[2025-06-29T17:38:59.426+0000] {standard_task_runner.py:107} ERROR - Failed to execute job 1632 for task dbt_task (Docker container failed: {'StatusCode': 2}; 173)
[2025-06-29T17:38:59.439+0000] {local_task_job_runner.py:234} INFO - Task exited with return code 1
[2025-06-29T17:38:59.463+0000] {taskinstance.py:3280} INFO - 0 downstream tasks scheduled from follow-on schedule check
