[2025-06-29T17:45:28.279+0000] {taskinstance.py:1956} INFO - Dependencies all met for dep_context=non-requeueable deps ti=<TaskInstance: films_dag_orchestaror.dbt_task scheduled__2025-06-29T17:44:00+00:00 [queued]>
[2025-06-29T17:45:28.287+0000] {taskinstance.py:1956} INFO - Dependencies all met for dep_context=requeueable deps ti=<TaskInstance: films_dag_orchestaror.dbt_task scheduled__2025-06-29T17:44:00+00:00 [queued]>
[2025-06-29T17:45:28.287+0000] {taskinstance.py:2170} INFO - Starting attempt 1 of 1
[2025-06-29T17:45:28.300+0000] {taskinstance.py:2191} INFO - Executing <Task(DockerOperator): dbt_task> on 2025-06-29 17:44:00+00:00
[2025-06-29T17:45:28.304+0000] {standard_task_runner.py:60} INFO - Started process 191 to run task
[2025-06-29T17:45:28.308+0000] {standard_task_runner.py:87} INFO - Running: ['airflow', 'tasks', 'run', 'films_dag_orchestaror', 'dbt_task', 'scheduled__2025-06-29T17:44:00+00:00', '--job-id', '5', '--raw', '--subdir', 'DAGS_FOLDER/orchestrator.py', '--cfg-path', '/tmp/tmp_pvpatux']
[2025-06-29T17:45:28.310+0000] {standard_task_runner.py:88} INFO - Job 5: Subtask dbt_task
[2025-06-29T17:45:28.374+0000] {task_command.py:423} INFO - Running <TaskInstance: films_dag_orchestaror.dbt_task scheduled__2025-06-29T17:44:00+00:00 [running]> on host 9909ba106c7b
[2025-06-29T17:45:28.456+0000] {taskinstance.py:2480} INFO - Exporting env vars: AIRFLOW_CTX_DAG_OWNER='airflow' AIRFLOW_CTX_DAG_ID='films_dag_orchestaror' AIRFLOW_CTX_TASK_ID='dbt_task' AIRFLOW_CTX_EXECUTION_DATE='2025-06-29T17:44:00+00:00' AIRFLOW_CTX_TRY_NUMBER='1' AIRFLOW_CTX_DAG_RUN_ID='scheduled__2025-06-29T17:44:00+00:00'
[2025-06-29T17:45:28.471+0000] {docker.py:486} INFO - Pulling docker image ghcr.io/dbt-labs/dbt-postgres:1.9.latest
[2025-06-29T17:45:30.109+0000] {docker.py:500} INFO - 1.9.latest: Pulling from dbt-labs/dbt-postgres
[2025-06-29T17:45:31.297+0000] {docker.py:500} INFO - ff6fd1a4e7c8: Pulling fs layer
[2025-06-29T17:45:31.297+0000] {docker.py:500} INFO - cfbc1b5c07ba: Pulling fs layer
[2025-06-29T17:45:31.298+0000] {docker.py:500} INFO - c8ed82ea4ded: Pulling fs layer
[2025-06-29T17:45:31.298+0000] {docker.py:500} INFO - 8d3558e77e43: Pulling fs layer
[2025-06-29T17:45:31.298+0000] {docker.py:500} INFO - 5de87e84afee: Pulling fs layer
[2025-06-29T17:45:31.299+0000] {docker.py:500} INFO - d2870f791e42: Pulling fs layer
[2025-06-29T17:45:31.299+0000] {docker.py:500} INFO - 1de84acd5556: Pulling fs layer
[2025-06-29T17:45:31.299+0000] {docker.py:500} INFO - 752715e5dadf: Pulling fs layer
[2025-06-29T17:45:31.300+0000] {docker.py:500} INFO - 6242c8ff2ef3: Pulling fs layer
[2025-06-29T17:45:31.881+0000] {docker.py:500} INFO - cfbc1b5c07ba: Downloading
[2025-06-29T17:45:31.980+0000] {docker.py:500} INFO - ff6fd1a4e7c8: Downloading
[2025-06-29T17:45:31.980+0000] {docker.py:500} INFO - d2870f791e42: Downloading
[2025-06-29T17:45:32.080+0000] {docker.py:500} INFO - c8ed82ea4ded: Downloading
[2025-06-29T17:45:32.380+0000] {docker.py:500} INFO - 5de87e84afee: Downloading
[2025-06-29T17:45:32.380+0000] {docker.py:500} INFO - 752715e5dadf: Downloading
[2025-06-29T17:45:32.780+0000] {docker.py:500} INFO - 6242c8ff2ef3: Downloading
[2025-06-29T17:45:33.081+0000] {docker.py:500} INFO - 8d3558e77e43: Downloading
[2025-06-29T17:45:33.081+0000] {docker.py:500} INFO - 1de84acd5556: Downloading
[2025-06-29T17:45:35.880+0000] {docker.py:500} INFO - d2870f791e42: Download complete
[2025-06-29T17:45:36.179+0000] {docker.py:500} INFO - c8ed82ea4ded: Download complete
[2025-06-29T17:45:36.180+0000] {docker.py:500} INFO - cfbc1b5c07ba: Download complete
[2025-06-29T17:45:36.979+0000] {docker.py:500} INFO - 1de84acd5556: Download complete
[2025-06-29T17:45:38.280+0000] {docker.py:500} INFO - 752715e5dadf: Download complete
[2025-06-29T17:45:38.879+0000] {docker.py:500} INFO - 5de87e84afee: Download complete
[2025-06-29T17:45:38.883+0000] {docker.py:500} INFO - 5de87e84afee: Extracting
[2025-06-29T17:45:40.680+0000] {docker.py:500} INFO - ff6fd1a4e7c8: Download complete
[2025-06-29T17:45:40.680+0000] {docker.py:500} INFO - 6242c8ff2ef3: Download complete
[2025-06-29T17:45:41.582+0000] {docker.py:500} INFO - 1de84acd5556: Extracting
[2025-06-29T17:45:41.584+0000] {docker.py:500} INFO - 5de87e84afee: Pull complete
[2025-06-29T17:45:42.480+0000] {docker.py:500} INFO - 8d3558e77e43: Download complete
[2025-06-29T17:45:42.483+0000] {docker.py:500} INFO - 1de84acd5556: Pull complete
[2025-06-29T17:45:42.583+0000] {docker.py:500} INFO - 752715e5dadf: Extracting
[2025-06-29T17:45:42.781+0000] {docker.py:500} INFO - 752715e5dadf: Pull complete
[2025-06-29T17:45:42.881+0000] {docker.py:500} INFO - c8ed82ea4ded: Pull complete
[2025-06-29T17:45:42.882+0000] {docker.py:500} INFO - cfbc1b5c07ba: Extracting
[2025-06-29T17:45:43.082+0000] {docker.py:500} INFO - cfbc1b5c07ba: Pull complete
[2025-06-29T17:45:43.085+0000] {docker.py:500} INFO - ff6fd1a4e7c8: Extracting
[2025-06-29T17:45:46.082+0000] {docker.py:500} INFO - ff6fd1a4e7c8: Pull complete
[2025-06-29T17:45:46.086+0000] {docker.py:500} INFO - 6242c8ff2ef3: Extracting
[2025-06-29T17:45:46.281+0000] {docker.py:500} INFO - 6242c8ff2ef3: Pull complete
[2025-06-29T17:45:46.380+0000] {docker.py:500} INFO - d2870f791e42: Pull complete
[2025-06-29T17:45:46.381+0000] {docker.py:500} INFO - 8d3558e77e43: Extracting
[2025-06-29T17:45:47.456+0000] {docker.py:500} INFO - 8d3558e77e43: Pull complete
[2025-06-29T17:45:47.456+0000] {docker.py:495} INFO - Digest: sha256:37624cce09877ff03fd5f6b01355fdf5a3462a1b651d40d8b8edc1cf056eedf0
[2025-06-29T17:45:47.456+0000] {docker.py:495} INFO - Status: Downloaded newer image for ghcr.io/dbt-labs/dbt-postgres:1.9.latest
[2025-06-29T17:45:47.458+0000] {docker.py:359} INFO - Starting docker container from image ghcr.io/dbt-labs/dbt-postgres:1.9.latest
[2025-06-29T17:45:47.469+0000] {docker.py:367} WARNING - Using remote engine or docker-in-docker and mounting temporary volume from host is not supported. Falling back to `mount_tmp_dir=False` mode. You can set `mount_tmp_dir` parameter to False to disable mounting and remove the warning
[2025-06-29T17:45:50.111+0000] {docker.py:429} INFO - [0m17:45:50  Running with dbt=1.9.0
[2025-06-29T17:45:50.425+0000] {docker.py:429} INFO - [0m17:45:50  Registered adapter: postgres=1.9.0
[2025-06-29T17:45:50.627+0000] {docker.py:429} INFO - [0m17:45:50  [[33mWARNING[0m]: Configuration paths exist in your dbt_project.yml file which do not apply to any resources.
There are 1 unused configuration paths:
- models.my_dbt_project.example
[2025-06-29T17:45:50.796+0000] {docker.py:429} INFO - [0m17:45:50  Found 3 models, 3 sources, 431 macros
[2025-06-29T17:45:50.799+0000] {docker.py:429} INFO - [0m17:45:50
[2025-06-29T17:45:50.800+0000] {docker.py:429} INFO - [0m17:45:50  Concurrency: 4 threads (target='dev')
[2025-06-29T17:45:50.800+0000] {docker.py:429} INFO - [0m17:45:50
[2025-06-29T17:45:50.924+0000] {docker.py:429} INFO - [0m17:45:50  1 of 3 START sql table model dev.film_rating ................................... [RUN]
[2025-06-29T17:45:50.925+0000] {docker.py:429} INFO - [0m17:45:50  2 of 3 START sql table model dev.staging ....................................... [RUN]
[2025-06-29T17:45:51.087+0000] {docker.py:429} INFO - [0m17:45:51  1 of 3 ERROR creating sql table model dev.film_rating .......................... [[31mERROR[0m in 0.16s]
[2025-06-29T17:45:51.088+0000] {docker.py:429} INFO - [0m17:45:51  2 of 3 ERROR creating sql table model dev.staging .............................. [[31mERROR[0m in 0.16s]
[2025-06-29T17:45:51.100+0000] {docker.py:429} INFO - [0m17:45:51  3 of 3 SKIP relation dev.film_actors ........................................... [[33mSKIP[0m]
[2025-06-29T17:45:51.118+0000] {docker.py:429} INFO - [0m17:45:51
[2025-06-29T17:45:51.118+0000] {docker.py:429} INFO - [0m17:45:51  Finished running 3 table models in 0 hours 0 minutes and 0.32 seconds (0.32s).
[2025-06-29T17:45:51.165+0000] {docker.py:429} INFO - [0m17:45:51
[2025-06-29T17:45:51.165+0000] {docker.py:429} INFO - [0m17:45:51  [31mCompleted with 2 errors, 0 partial successes, and 0 warnings:[0m
[2025-06-29T17:45:51.166+0000] {docker.py:429} INFO - [0m17:45:51
[2025-06-29T17:45:51.167+0000] {docker.py:429} INFO - [0m17:45:51    Database Error in model film_rating (models/staging/film_rating.sql)
  relation "film_rating" already exists
  compiled code at target/run/my_dbt_project/models/staging/film_rating.sql
[2025-06-29T17:45:51.168+0000] {docker.py:429} INFO - [0m17:45:51
[2025-06-29T17:45:51.168+0000] {docker.py:429} INFO - [0m17:45:51    Database Error in model staging (models/staging/staging.sql)
  relation "staging" already exists
  compiled code at target/run/my_dbt_project/models/staging/staging.sql
[2025-06-29T17:45:51.169+0000] {docker.py:429} INFO - [0m17:45:51
[2025-06-29T17:45:51.170+0000] {docker.py:429} INFO - [0m17:45:51  Done. PASS=0 WARN=0 ERROR=2 SKIP=1 TOTAL=3
[2025-06-29T17:45:52.266+0000] {taskinstance.py:2698} ERROR - Task failed with exception
Traceback (most recent call last):
  File "/home/airflow/.local/lib/python3.10/site-packages/docker/api/client.py", line 265, in _raise_for_status
    response.raise_for_status()
  File "/home/airflow/.local/lib/python3.10/site-packages/requests/models.py", line 1021, in raise_for_status
    raise HTTPError(http_error_msg, response=self)
requests.exceptions.HTTPError: 400 Client Error: Bad Request for url: http+docker://localhost/v1.49/containers/create

The above exception was the direct cause of the following exception:

Traceback (most recent call last):
  File "/home/airflow/.local/lib/python3.10/site-packages/airflow/providers/docker/operators/docker.py", line 364, in _run_image
    return self._run_image_with_mounts([*self.mounts, tmp_mount], add_tmp_variable=True)
  File "/home/airflow/.local/lib/python3.10/site-packages/airflow/providers/docker/operators/docker.py", line 391, in _run_image_with_mounts
    self.container = self.cli.create_container(
  File "/home/airflow/.local/lib/python3.10/site-packages/docker/api/container.py", line 439, in create_container
    return self.create_container_from_config(config, name, platform)
  File "/home/airflow/.local/lib/python3.10/site-packages/docker/api/container.py", line 456, in create_container_from_config
    return self._result(res, True)
  File "/home/airflow/.local/lib/python3.10/site-packages/docker/api/client.py", line 271, in _result
    self._raise_for_status(response)
  File "/home/airflow/.local/lib/python3.10/site-packages/docker/api/client.py", line 267, in _raise_for_status
    raise create_api_error_from_http_exception(e) from e
  File "/home/airflow/.local/lib/python3.10/site-packages/docker/errors.py", line 39, in create_api_error_from_http_exception
    raise cls(e, response=response, explanation=explanation) from e
docker.errors.APIError: 400 Client Error for http+docker://localhost/v1.49/containers/create: Bad Request ("invalid mount config for type "bind": bind source path does not exist: /tmp/airflowtmpes5f9sxv")

During handling of the above exception, another exception occurred:

Traceback (most recent call last):
  File "/home/airflow/.local/lib/python3.10/site-packages/airflow/models/taskinstance.py", line 433, in _execute_task
    result = execute_callable(context=context, **execute_callable_kwargs)
  File "/home/airflow/.local/lib/python3.10/site-packages/airflow/providers/docker/operators/docker.py", line 502, in execute
    return self._run_image()
  File "/home/airflow/.local/lib/python3.10/site-packages/airflow/providers/docker/operators/docker.py", line 373, in _run_image
    return self._run_image_with_mounts(self.mounts, add_tmp_variable=False)
  File "/home/airflow/.local/lib/python3.10/site-packages/airflow/providers/docker/operators/docker.py", line 437, in _run_image_with_mounts
    raise DockerContainerFailedException(f"Docker container failed: {result!r}", logs=log_lines)
airflow.providers.docker.exceptions.DockerContainerFailedException: Docker container failed: {'StatusCode': 1}
[2025-06-29T17:45:52.272+0000] {taskinstance.py:1138} INFO - Marking task as FAILED. dag_id=films_dag_orchestaror, task_id=dbt_task, execution_date=20250629T174400, start_date=20250629T174528, end_date=20250629T174552
[2025-06-29T17:45:52.291+0000] {standard_task_runner.py:107} ERROR - Failed to execute job 5 for task dbt_task (Docker container failed: {'StatusCode': 1}; 191)
[2025-06-29T17:45:52.314+0000] {local_task_job_runner.py:234} INFO - Task exited with return code 1
[2025-06-29T17:45:52.334+0000] {taskinstance.py:3280} INFO - 0 downstream tasks scheduled from follow-on schedule check
