[2025-06-29T04:57:50.845+0000] {taskinstance.py:1956} INFO - Dependencies all met for dep_context=non-requeueable deps ti=<TaskInstance: films_dag_orchestaror.run_etl_script scheduled__2025-06-29T03:33:00+00:00 [queued]>
[2025-06-29T04:57:50.854+0000] {taskinstance.py:1956} INFO - Dependencies all met for dep_context=requeueable deps ti=<TaskInstance: films_dag_orchestaror.run_etl_script scheduled__2025-06-29T03:33:00+00:00 [queued]>
[2025-06-29T04:57:50.854+0000] {taskinstance.py:2170} INFO - Starting attempt 1 of 1
[2025-06-29T04:57:50.871+0000] {taskinstance.py:2191} INFO - Executing <Task(PythonOperator): run_etl_script> on 2025-06-29 03:33:00+00:00
[2025-06-29T04:57:50.875+0000] {standard_task_runner.py:60} INFO - Started process 7391 to run task
[2025-06-29T04:57:50.879+0000] {standard_task_runner.py:87} INFO - Running: ['airflow', 'tasks', 'run', 'films_dag_orchestaror', 'run_etl_script', 'scheduled__2025-06-29T03:33:00+00:00', '--job-id', '1816', '--raw', '--subdir', 'DAGS_FOLDER/orchestrator.py', '--cfg-path', '/tmp/tmpmc01613c']
[2025-06-29T04:57:50.881+0000] {standard_task_runner.py:88} INFO - Job 1816: Subtask run_etl_script
[2025-06-29T04:57:50.959+0000] {task_command.py:423} INFO - Running <TaskInstance: films_dag_orchestaror.run_etl_script scheduled__2025-06-29T03:33:00+00:00 [running]> on host 1b1e07855000
[2025-06-29T04:57:51.069+0000] {taskinstance.py:2480} INFO - Exporting env vars: AIRFLOW_CTX_DAG_OWNER='airflow' AIRFLOW_CTX_DAG_ID='films_dag_orchestaror' AIRFLOW_CTX_TASK_ID='run_etl_script' AIRFLOW_CTX_EXECUTION_DATE='2025-06-29T03:33:00+00:00' AIRFLOW_CTX_TRY_NUMBER='1' AIRFLOW_CTX_DAG_RUN_ID='scheduled__2025-06-29T03:33:00+00:00'
[2025-06-29T04:57:51.177+0000] {taskinstance.py:2698} ERROR - Task failed with exception
Traceback (most recent call last):
  File "/home/airflow/.local/lib/python3.10/site-packages/airflow/models/taskinstance.py", line 433, in _execute_task
    result = execute_callable(context=context, **execute_callable_kwargs)
  File "/home/airflow/.local/lib/python3.10/site-packages/airflow/operators/python.py", line 199, in execute
    return_value = self.execute_callable()
  File "/home/airflow/.local/lib/python3.10/site-packages/airflow/operators/python.py", line 216, in execute_callable
    return self.python_callable(*self.op_args, **self.op_kwargs)
  File "/opt/airflow/dags/orchestrator.py", line 18, in run_etl_script
    raise Exception(result.stderr)
Exception: pg_dump: error: aborting because of server version mismatch
pg_dump: detail: server version: 17.5 (Debian 17.5-1.pgdg120+1); pg_dump version: 16.2 (Debian 16.2-1.pgdg120+2)
Traceback (most recent call last):
  File "/opt/airflow/etl/etl.py", line 61, in <module>
    subprocess.run(dump_comand,env=subprocess_env,check=True)
  File "/usr/local/lib/python3.10/subprocess.py", line 526, in run
    raise CalledProcessError(retcode, process.args,
subprocess.CalledProcessError: Command '['pg_dump', '-h', 'source_postgres', '-U', 'postgres', '-d', 'source_db', '-f', 'data_dump.sql', '-w']' returned non-zero exit status 1.

[2025-06-29T04:57:51.188+0000] {taskinstance.py:1138} INFO - Marking task as FAILED. dag_id=films_dag_orchestaror, task_id=run_etl_script, execution_date=20250629T033300, start_date=20250629T045750, end_date=20250629T045751
[2025-06-29T04:57:51.199+0000] {standard_task_runner.py:107} ERROR - Failed to execute job 1816 for task run_etl_script (pg_dump: error: aborting because of server version mismatch
pg_dump: detail: server version: 17.5 (Debian 17.5-1.pgdg120+1); pg_dump version: 16.2 (Debian 16.2-1.pgdg120+2)
Traceback (most recent call last):
  File "/opt/airflow/etl/etl.py", line 61, in <module>
    subprocess.run(dump_comand,env=subprocess_env,check=True)
  File "/usr/local/lib/python3.10/subprocess.py", line 526, in run
    raise CalledProcessError(retcode, process.args,
subprocess.CalledProcessError: Command '['pg_dump', '-h', 'source_postgres', '-U', 'postgres', '-d', 'source_db', '-f', 'data_dump.sql', '-w']' returned non-zero exit status 1.
; 7391)
[2025-06-29T04:57:51.221+0000] {local_task_job_runner.py:234} INFO - Task exited with return code 1
[2025-06-29T04:57:51.242+0000] {taskinstance.py:3280} INFO - 0 downstream tasks scheduled from follow-on schedule check
