[2025-06-29T06:50:00.879+0000] {taskinstance.py:1956} INFO - Dependencies all met for dep_context=non-requeueable deps ti=<TaskInstance: films_dag_orchestaror.run_etl_script scheduled__2025-06-29T06:49:00+00:00 [queued]>
[2025-06-29T06:50:00.887+0000] {taskinstance.py:1956} INFO - Dependencies all met for dep_context=requeueable deps ti=<TaskInstance: films_dag_orchestaror.run_etl_script scheduled__2025-06-29T06:49:00+00:00 [queued]>
[2025-06-29T06:50:00.887+0000] {taskinstance.py:2170} INFO - Starting attempt 1 of 1
[2025-06-29T06:50:00.899+0000] {taskinstance.py:2191} INFO - Executing <Task(PythonOperator): run_etl_script> on 2025-06-29 06:49:00+00:00
[2025-06-29T06:50:00.902+0000] {standard_task_runner.py:60} INFO - Started process 601 to run task
[2025-06-29T06:50:00.905+0000] {standard_task_runner.py:87} INFO - Running: ['airflow', 'tasks', 'run', 'films_dag_orchestaror', 'run_etl_script', 'scheduled__2025-06-29T06:49:00+00:00', '--job-id', '1628', '--raw', '--subdir', 'DAGS_FOLDER/orchestrator.py', '--cfg-path', '/tmp/tmpnsau2g6u']
[2025-06-29T06:50:00.907+0000] {standard_task_runner.py:88} INFO - Job 1628: Subtask run_etl_script
[2025-06-29T06:50:00.959+0000] {task_command.py:423} INFO - Running <TaskInstance: films_dag_orchestaror.run_etl_script scheduled__2025-06-29T06:49:00+00:00 [running]> on host c3520c5c5ff0
[2025-06-29T06:50:01.321+0000] {taskinstance.py:2480} INFO - Exporting env vars: AIRFLOW_CTX_DAG_OWNER='airflow' AIRFLOW_CTX_DAG_ID='films_dag_orchestaror' AIRFLOW_CTX_TASK_ID='run_etl_script' AIRFLOW_CTX_EXECUTION_DATE='2025-06-29T06:49:00+00:00' AIRFLOW_CTX_TRY_NUMBER='1' AIRFLOW_CTX_DAG_RUN_ID='scheduled__2025-06-29T06:49:00+00:00'
[2025-06-29T06:51:08.148+0000] {taskinstance.py:2698} ERROR - Task failed with exception
Traceback (most recent call last):
  File "/home/airflow/.local/lib/python3.10/site-packages/airflow/models/taskinstance.py", line 433, in _execute_task
    result = execute_callable(context=context, **execute_callable_kwargs)
  File "/home/airflow/.local/lib/python3.10/site-packages/airflow/operators/python.py", line 199, in execute
    return_value = self.execute_callable()
  File "/home/airflow/.local/lib/python3.10/site-packages/airflow/operators/python.py", line 216, in execute_callable
    return self.python_callable(*self.op_args, **self.op_kwargs)
  File "/opt/airflow/dags/orchestrator.py", line 17, in run_etl_script
    raise Exception(result.stderr)
Exception: psql:data_dump.sql:31: ERROR:  relation "actors" already exists
psql:data_dump.sql:34: FATAL:  terminating connection due to administrator command
psql:data_dump.sql:34: server closed the connection unexpectedly
	This probably means the server terminated abnormally
	before or while processing the request.
psql:data_dump.sql:34: error: connection to server was lost
Traceback (most recent call last):
  File "/opt/airflow/etl/etl.py", line 74, in <module>
    subprocess.run(load_command,env=subprocess_env,check=True)
  File "/usr/local/lib/python3.10/subprocess.py", line 526, in run
    raise CalledProcessError(retcode, process.args,
subprocess.CalledProcessError: Command '['psql', '-h', 'destination_postgres', '-U', 'postgres', '-d', 'destination_db', '-a', '-f', 'data_dump.sql']' returned non-zero exit status 2.

[2025-06-29T06:51:08.168+0000] {taskinstance.py:1138} INFO - Marking task as FAILED. dag_id=films_dag_orchestaror, task_id=run_etl_script, execution_date=20250629T064900, start_date=20250629T065000, end_date=20250629T065108
[2025-06-29T06:51:08.192+0000] {standard_task_runner.py:107} ERROR - Failed to execute job 1628 for task run_etl_script (psql:data_dump.sql:31: ERROR:  relation "actors" already exists
psql:data_dump.sql:34: FATAL:  terminating connection due to administrator command
psql:data_dump.sql:34: server closed the connection unexpectedly
	This probably means the server terminated abnormally
	before or while processing the request.
psql:data_dump.sql:34: error: connection to server was lost
Traceback (most recent call last):
  File "/opt/airflow/etl/etl.py", line 74, in <module>
    subprocess.run(load_command,env=subprocess_env,check=True)
  File "/usr/local/lib/python3.10/subprocess.py", line 526, in run
    raise CalledProcessError(retcode, process.args,
subprocess.CalledProcessError: Command '['psql', '-h', 'destination_postgres', '-U', 'postgres', '-d', 'destination_db', '-a', '-f', 'data_dump.sql']' returned non-zero exit status 2.
; 601)
[2025-06-29T06:51:08.240+0000] {local_task_job_runner.py:234} INFO - Task exited with return code 1
[2025-06-29T06:51:08.277+0000] {taskinstance.py:3280} INFO - 0 downstream tasks scheduled from follow-on schedule check
