[2025-06-29T06:36:28.169+0000] {taskinstance.py:1956} INFO - Dependencies all met for dep_context=non-requeueable deps ti=<TaskInstance: films_dag_orchestaror.dbt_task manual__2025-06-29T06:36:25.653790+00:00 [queued]>
[2025-06-29T06:36:28.177+0000] {taskinstance.py:1956} INFO - Dependencies all met for dep_context=requeueable deps ti=<TaskInstance: films_dag_orchestaror.dbt_task manual__2025-06-29T06:36:25.653790+00:00 [queued]>
[2025-06-29T06:36:28.177+0000] {taskinstance.py:2170} INFO - Starting attempt 1 of 1
[2025-06-29T06:36:28.188+0000] {taskinstance.py:2191} INFO - Executing <Task(DockerOperator): dbt_task> on 2025-06-29 06:36:25.653790+00:00
[2025-06-29T06:36:28.192+0000] {standard_task_runner.py:60} INFO - Started process 343 to run task
[2025-06-29T06:36:28.195+0000] {standard_task_runner.py:87} INFO - Running: ['airflow', 'tasks', 'run', 'films_dag_orchestaror', 'dbt_task', 'manual__2025-06-29T06:36:25.653790+00:00', '--job-id', '1603', '--raw', '--subdir', 'DAGS_FOLDER/orchestrator.py', '--cfg-path', '/tmp/tmp93qlxy3m']
[2025-06-29T06:36:28.197+0000] {standard_task_runner.py:88} INFO - Job 1603: Subtask dbt_task
[2025-06-29T06:36:28.247+0000] {task_command.py:423} INFO - Running <TaskInstance: films_dag_orchestaror.dbt_task manual__2025-06-29T06:36:25.653790+00:00 [running]> on host c3520c5c5ff0
[2025-06-29T06:36:28.333+0000] {taskinstance.py:2480} INFO - Exporting env vars: AIRFLOW_CTX_DAG_OWNER='airflow' AIRFLOW_CTX_DAG_ID='films_dag_orchestaror' AIRFLOW_CTX_TASK_ID='dbt_task' AIRFLOW_CTX_EXECUTION_DATE='2025-06-29T06:36:25.653790+00:00' AIRFLOW_CTX_TRY_NUMBER='1' AIRFLOW_CTX_DAG_RUN_ID='manual__2025-06-29T06:36:25.653790+00:00'
[2025-06-29T06:36:28.347+0000] {docker.py:486} INFO - Pulling docker image ghcr.io/dbt-labs/dbt-postgres:1.9.latest
[2025-06-29T06:36:30.191+0000] {docker.py:500} INFO - 1.9.latest: Pulling from dbt-labs/dbt-postgres
[2025-06-29T06:36:30.810+0000] {docker.py:500} INFO - 8d3558e77e43: Pulling fs layer
[2025-06-29T06:36:30.810+0000] {docker.py:500} INFO - c8ed82ea4ded: Pulling fs layer
[2025-06-29T06:36:30.811+0000] {docker.py:500} INFO - cfbc1b5c07ba: Pulling fs layer
[2025-06-29T06:36:30.811+0000] {docker.py:500} INFO - 5de87e84afee: Pulling fs layer
[2025-06-29T06:36:30.812+0000] {docker.py:500} INFO - ff6fd1a4e7c8: Pulling fs layer
[2025-06-29T06:36:30.812+0000] {docker.py:500} INFO - 1de84acd5556: Pulling fs layer
[2025-06-29T06:36:30.812+0000] {docker.py:500} INFO - 6242c8ff2ef3: Pulling fs layer
[2025-06-29T06:36:30.813+0000] {docker.py:500} INFO - d2870f791e42: Pulling fs layer
[2025-06-29T06:36:30.813+0000] {docker.py:500} INFO - 752715e5dadf: Pulling fs layer
[2025-06-29T06:36:31.055+0000] {docker.py:500} INFO - c8ed82ea4ded: Download complete
[2025-06-29T06:36:31.455+0000] {docker.py:500} INFO - d2870f791e42: Download complete
[2025-06-29T06:36:31.555+0000] {docker.py:500} INFO - 1de84acd5556: Download complete
[2025-06-29T06:36:31.556+0000] {docker.py:500} INFO - 752715e5dadf: Downloading
[2025-06-29T06:36:31.655+0000] {docker.py:500} INFO - ff6fd1a4e7c8: Downloading
[2025-06-29T06:36:31.855+0000] {docker.py:500} INFO - 6242c8ff2ef3: Downloading
[2025-06-29T06:36:32.155+0000] {docker.py:500} INFO - 5de87e84afee: Downloading
[2025-06-29T06:36:32.256+0000] {docker.py:500} INFO - 752715e5dadf: Download complete
[2025-06-29T06:36:32.455+0000] {docker.py:500} INFO - 6242c8ff2ef3: Download complete
[2025-06-29T06:36:32.456+0000] {docker.py:500} INFO - cfbc1b5c07ba: Downloading
[2025-06-29T06:36:32.655+0000] {docker.py:500} INFO - 8d3558e77e43: Downloading
[2025-06-29T06:36:35.855+0000] {docker.py:500} INFO - 5de87e84afee: Download complete
[2025-06-29T06:36:35.861+0000] {docker.py:500} INFO - 5de87e84afee: Extracting
[2025-06-29T06:36:36.557+0000] {docker.py:500} INFO - cfbc1b5c07ba: Download complete
[2025-06-29T06:36:36.856+0000] {docker.py:500} INFO - ff6fd1a4e7c8: Download complete
[2025-06-29T06:36:36.858+0000] {docker.py:500} INFO - 1de84acd5556: Extracting
[2025-06-29T06:36:36.860+0000] {docker.py:500} INFO - 5de87e84afee: Pull complete
[2025-06-29T06:36:36.957+0000] {docker.py:500} INFO - 1de84acd5556: Pull complete
[2025-06-29T06:36:36.958+0000] {docker.py:500} INFO - 752715e5dadf: Extracting
[2025-06-29T06:36:37.256+0000] {docker.py:500} INFO - c8ed82ea4ded: Pull complete
[2025-06-29T06:36:37.257+0000] {docker.py:500} INFO - 752715e5dadf: Pull complete
[2025-06-29T06:36:37.259+0000] {docker.py:500} INFO - cfbc1b5c07ba: Extracting
[2025-06-29T06:36:37.557+0000] {docker.py:500} INFO - cfbc1b5c07ba: Pull complete
[2025-06-29T06:36:37.558+0000] {docker.py:500} INFO - ff6fd1a4e7c8: Extracting
[2025-06-29T06:36:40.457+0000] {docker.py:500} INFO - 6242c8ff2ef3: Extracting
[2025-06-29T06:36:40.457+0000] {docker.py:500} INFO - ff6fd1a4e7c8: Pull complete
[2025-06-29T06:36:40.655+0000] {docker.py:500} INFO - 8d3558e77e43: Download complete
[2025-06-29T06:36:40.656+0000] {docker.py:500} INFO - 6242c8ff2ef3: Pull complete
[2025-06-29T06:36:40.756+0000] {docker.py:500} INFO - d2870f791e42: Pull complete
[2025-06-29T06:36:40.756+0000] {docker.py:500} INFO - 8d3558e77e43: Extracting
[2025-06-29T06:36:41.856+0000] {docker.py:500} INFO - 8d3558e77e43: Pull complete
[2025-06-29T06:36:41.862+0000] {docker.py:495} INFO - Digest: sha256:37624cce09877ff03fd5f6b01355fdf5a3462a1b651d40d8b8edc1cf056eedf0
[2025-06-29T06:36:41.863+0000] {docker.py:495} INFO - Status: Downloaded newer image for ghcr.io/dbt-labs/dbt-postgres:1.9.latest
[2025-06-29T06:36:41.864+0000] {docker.py:359} INFO - Starting docker container from image ghcr.io/dbt-labs/dbt-postgres:1.9.latest
[2025-06-29T06:36:41.874+0000] {docker.py:367} WARNING - Using remote engine or docker-in-docker and mounting temporary volume from host is not supported. Falling back to `mount_tmp_dir=False` mode. You can set `mount_tmp_dir` parameter to False to disable mounting and remove the warning
[2025-06-29T06:36:42.667+0000] {taskinstance.py:2698} ERROR - Task failed with exception
Traceback (most recent call last):
  File "/home/airflow/.local/lib/python3.10/site-packages/docker/api/client.py", line 265, in _raise_for_status
    response.raise_for_status()
  File "/home/airflow/.local/lib/python3.10/site-packages/requests/models.py", line 1021, in raise_for_status
    raise HTTPError(http_error_msg, response=self)
requests.exceptions.HTTPError: 400 Client Error: Bad Request for url: http+docker://localhost/v1.49/containers/create

The above exception was the direct cause of the following exception:

Traceback (most recent call last):
  File "/home/airflow/.local/lib/python3.10/site-packages/airflow/providers/docker/operators/docker.py", line 364, in _run_image
    return self._run_image_with_mounts([*self.mounts, tmp_mount], add_tmp_variable=True)
  File "/home/airflow/.local/lib/python3.10/site-packages/airflow/providers/docker/operators/docker.py", line 391, in _run_image_with_mounts
    self.container = self.cli.create_container(
  File "/home/airflow/.local/lib/python3.10/site-packages/docker/api/container.py", line 439, in create_container
    return self.create_container_from_config(config, name, platform)
  File "/home/airflow/.local/lib/python3.10/site-packages/docker/api/container.py", line 456, in create_container_from_config
    return self._result(res, True)
  File "/home/airflow/.local/lib/python3.10/site-packages/docker/api/client.py", line 271, in _result
    self._raise_for_status(response)
  File "/home/airflow/.local/lib/python3.10/site-packages/docker/api/client.py", line 267, in _raise_for_status
    raise create_api_error_from_http_exception(e) from e
  File "/home/airflow/.local/lib/python3.10/site-packages/docker/errors.py", line 39, in create_api_error_from_http_exception
    raise cls(e, response=response, explanation=explanation) from e
docker.errors.APIError: 400 Client Error for http+docker://localhost/v1.49/containers/create: Bad Request ("invalid mount config for type "bind": bind source path does not exist: /tmp/airflowtmpxnmk1d0e")

During handling of the above exception, another exception occurred:

Traceback (most recent call last):
  File "/home/airflow/.local/lib/python3.10/site-packages/docker/api/client.py", line 265, in _raise_for_status
    response.raise_for_status()
  File "/home/airflow/.local/lib/python3.10/site-packages/requests/models.py", line 1021, in raise_for_status
    raise HTTPError(http_error_msg, response=self)
requests.exceptions.HTTPError: 404 Client Error: Not Found for url: http+docker://localhost/v1.49/containers/1790a2791da70d23588395b703d21ca384ae86e4b4ebf4c5956b2e9828c99a38/start

The above exception was the direct cause of the following exception:

Traceback (most recent call last):
  File "/home/airflow/.local/lib/python3.10/site-packages/airflow/models/taskinstance.py", line 433, in _execute_task
    result = execute_callable(context=context, **execute_callable_kwargs)
  File "/home/airflow/.local/lib/python3.10/site-packages/airflow/providers/docker/operators/docker.py", line 502, in execute
    return self._run_image()
  File "/home/airflow/.local/lib/python3.10/site-packages/airflow/providers/docker/operators/docker.py", line 373, in _run_image
    return self._run_image_with_mounts(self.mounts, add_tmp_variable=False)
  File "/home/airflow/.local/lib/python3.10/site-packages/airflow/providers/docker/operators/docker.py", line 423, in _run_image_with_mounts
    self.cli.start(self.container["Id"])
  File "/home/airflow/.local/lib/python3.10/site-packages/docker/utils/decorators.py", line 19, in wrapped
    return f(self, resource_id, *args, **kwargs)
  File "/home/airflow/.local/lib/python3.10/site-packages/docker/api/container.py", line 1135, in start
    self._raise_for_status(res)
  File "/home/airflow/.local/lib/python3.10/site-packages/docker/api/client.py", line 267, in _raise_for_status
    raise create_api_error_from_http_exception(e) from e
  File "/home/airflow/.local/lib/python3.10/site-packages/docker/errors.py", line 39, in create_api_error_from_http_exception
    raise cls(e, response=response, explanation=explanation) from e
docker.errors.NotFound: 404 Client Error for http+docker://localhost/v1.49/containers/1790a2791da70d23588395b703d21ca384ae86e4b4ebf4c5956b2e9828c99a38/start: Not Found ("failed to set up container networking: network my_network not found")
[2025-06-29T06:36:42.685+0000] {taskinstance.py:1138} INFO - Marking task as FAILED. dag_id=films_dag_orchestaror, task_id=dbt_task, execution_date=20250629T063625, start_date=20250629T063628, end_date=20250629T063642
[2025-06-29T06:36:42.700+0000] {standard_task_runner.py:107} ERROR - Failed to execute job 1603 for task dbt_task (404 Client Error for http+docker://localhost/v1.49/containers/1790a2791da70d23588395b703d21ca384ae86e4b4ebf4c5956b2e9828c99a38/start: Not Found ("failed to set up container networking: network my_network not found"); 343)
[2025-06-29T06:36:42.871+0000] {local_task_job_runner.py:234} INFO - Task exited with return code 1
[2025-06-29T06:36:42.895+0000] {taskinstance.py:3280} INFO - 0 downstream tasks scheduled from follow-on schedule check
