[2025-06-28T05:54:45.622+0000] {taskinstance.py:1956} INFO - Dependencies all met for dep_context=non-requeueable deps ti=<TaskInstance: films_dag_orchestaror.run_etl_script manual__2025-06-28T05:54:44.264974+00:00 [queued]>
[2025-06-28T05:54:45.634+0000] {taskinstance.py:1956} INFO - Dependencies all met for dep_context=requeueable deps ti=<TaskInstance: films_dag_orchestaror.run_etl_script manual__2025-06-28T05:54:44.264974+00:00 [queued]>
[2025-06-28T05:54:45.636+0000] {taskinstance.py:2170} INFO - Starting attempt 1 of 1
[2025-06-28T05:54:45.723+0000] {taskinstance.py:2191} INFO - Executing <Task(PythonOperator): run_etl_script> on 2025-06-28 05:54:44.264974+00:00
[2025-06-28T05:54:45.730+0000] {standard_task_runner.py:60} INFO - Started process 177 to run task
[2025-06-28T05:54:45.737+0000] {standard_task_runner.py:87} INFO - Running: ['airflow', 'tasks', 'run', 'films_dag_orchestaror', 'run_etl_script', 'manual__2025-06-28T05:54:44.264974+00:00', '--job-id', '167', '--raw', '--subdir', 'DAGS_FOLDER/orchestrator.py', '--cfg-path', '/tmp/tmpngnmvzwg']
[2025-06-28T05:54:45.740+0000] {standard_task_runner.py:88} INFO - Job 167: Subtask run_etl_script
[2025-06-28T05:54:45.881+0000] {task_command.py:423} INFO - Running <TaskInstance: films_dag_orchestaror.run_etl_script manual__2025-06-28T05:54:44.264974+00:00 [running]> on host 7671ab806bce
[2025-06-28T05:54:46.083+0000] {taskinstance.py:2480} INFO - Exporting env vars: AIRFLOW_CTX_DAG_OWNER='airflow' AIRFLOW_CTX_DAG_ID='films_dag_orchestaror' AIRFLOW_CTX_TASK_ID='run_etl_script' AIRFLOW_CTX_EXECUTION_DATE='2025-06-28T05:54:44.264974+00:00' AIRFLOW_CTX_TRY_NUMBER='1' AIRFLOW_CTX_DAG_RUN_ID='manual__2025-06-28T05:54:44.264974+00:00'
[2025-06-28T05:55:12.572+0000] {taskinstance.py:2698} ERROR - Task failed with exception
Traceback (most recent call last):
  File "/home/airflow/.local/lib/python3.10/site-packages/airflow/models/taskinstance.py", line 433, in _execute_task
    result = execute_callable(context=context, **execute_callable_kwargs)
  File "/home/airflow/.local/lib/python3.10/site-packages/airflow/operators/python.py", line 199, in execute
    return_value = self.execute_callable()
  File "/home/airflow/.local/lib/python3.10/site-packages/airflow/operators/python.py", line 216, in execute_callable
    return self.python_callable(*self.op_args, **self.op_kwargs)
  File "/opt/airflow/dags/orchestrator.py", line 18, in run_etl_script
    raise Exception("Error aca " + result.stderr)
Exception: Error aca 
[2025-06-28T05:55:12.591+0000] {taskinstance.py:1138} INFO - Marking task as FAILED. dag_id=films_dag_orchestaror, task_id=run_etl_script, execution_date=20250628T055444, start_date=20250628T055445, end_date=20250628T055512
[2025-06-28T05:55:12.615+0000] {standard_task_runner.py:107} ERROR - Failed to execute job 167 for task run_etl_script (Error aca ; 177)
[2025-06-28T05:55:12.669+0000] {local_task_job_runner.py:234} INFO - Task exited with return code 1
[2025-06-28T05:55:12.698+0000] {taskinstance.py:3280} INFO - 0 downstream tasks scheduled from follow-on schedule check
