[2025-06-29T04:44:12.799+0000] {taskinstance.py:1956} INFO - Dependencies all met for dep_context=non-requeueable deps ti=<TaskInstance: films_dag_orchestaror.run_etl_script scheduled__2025-06-28T03:06:00+00:00 [queued]>
[2025-06-29T04:44:12.815+0000] {taskinstance.py:1956} INFO - Dependencies all met for dep_context=requeueable deps ti=<TaskInstance: films_dag_orchestaror.run_etl_script scheduled__2025-06-28T03:06:00+00:00 [queued]>
[2025-06-29T04:44:12.816+0000] {taskinstance.py:2170} INFO - Starting attempt 3 of 1
[2025-06-29T04:44:12.852+0000] {taskinstance.py:2191} INFO - Executing <Task(PythonOperator): run_etl_script> on 2025-06-28 03:06:00+00:00
[2025-06-29T04:44:12.864+0000] {standard_task_runner.py:60} INFO - Started process 185 to run task
[2025-06-29T04:44:12.883+0000] {standard_task_runner.py:87} INFO - Running: ['airflow', 'tasks', 'run', 'films_dag_orchestaror', 'run_etl_script', 'scheduled__2025-06-28T03:06:00+00:00', '--job-id', '314', '--raw', '--subdir', 'DAGS_FOLDER/orchestrator.py', '--cfg-path', '/tmp/tmpu19i3slt']
[2025-06-29T04:44:12.888+0000] {standard_task_runner.py:88} INFO - Job 314: Subtask run_etl_script
[2025-06-29T04:44:13.004+0000] {task_command.py:423} INFO - Running <TaskInstance: films_dag_orchestaror.run_etl_script scheduled__2025-06-28T03:06:00+00:00 [running]> on host 835dfac2f445
[2025-06-29T04:44:13.193+0000] {taskinstance.py:2480} INFO - Exporting env vars: AIRFLOW_CTX_DAG_OWNER='airflow' AIRFLOW_CTX_DAG_ID='films_dag_orchestaror' AIRFLOW_CTX_TASK_ID='run_etl_script' AIRFLOW_CTX_EXECUTION_DATE='2025-06-28T03:06:00+00:00' AIRFLOW_CTX_TRY_NUMBER='3' AIRFLOW_CTX_DAG_RUN_ID='scheduled__2025-06-28T03:06:00+00:00'
[2025-06-29T04:44:39.116+0000] {taskinstance.py:2698} ERROR - Task failed with exception
Traceback (most recent call last):
  File "/home/airflow/.local/lib/python3.10/site-packages/airflow/models/taskinstance.py", line 433, in _execute_task
    result = execute_callable(context=context, **execute_callable_kwargs)
  File "/home/airflow/.local/lib/python3.10/site-packages/airflow/operators/python.py", line 199, in execute
    return_value = self.execute_callable()
  File "/home/airflow/.local/lib/python3.10/site-packages/airflow/operators/python.py", line 216, in execute_callable
    return self.python_callable(*self.op_args, **self.op_kwargs)
  File "/opt/airflow/dags/orchestrator.py", line 18, in run_etl_script
    raise Exception(result.stderr)
Exception
[2025-06-29T04:44:39.136+0000] {taskinstance.py:1138} INFO - Marking task as FAILED. dag_id=films_dag_orchestaror, task_id=run_etl_script, execution_date=20250628T030600, start_date=20250629T044412, end_date=20250629T044439
[2025-06-29T04:44:39.165+0000] {standard_task_runner.py:107} ERROR - Failed to execute job 314 for task run_etl_script (; 185)
[2025-06-29T04:44:39.223+0000] {local_task_job_runner.py:234} INFO - Task exited with return code 1
[2025-06-29T04:44:39.251+0000] {taskinstance.py:3280} INFO - 0 downstream tasks scheduled from follow-on schedule check
