[2025-06-28T05:59:35.353+0000] {taskinstance.py:1956} INFO - Dependencies all met for dep_context=non-requeueable deps ti=<TaskInstance: films_dag_orchestaror.run_etl_script scheduled__2025-06-28T02:55:00+00:00 [queued]>
[2025-06-28T05:59:35.365+0000] {taskinstance.py:1956} INFO - Dependencies all met for dep_context=requeueable deps ti=<TaskInstance: films_dag_orchestaror.run_etl_script scheduled__2025-06-28T02:55:00+00:00 [queued]>
[2025-06-28T05:59:35.366+0000] {taskinstance.py:2170} INFO - Starting attempt 2 of 1
[2025-06-28T05:59:35.393+0000] {taskinstance.py:2191} INFO - Executing <Task(PythonOperator): run_etl_script> on 2025-06-28 02:55:00+00:00
[2025-06-28T05:59:35.401+0000] {standard_task_runner.py:60} INFO - Started process 181 to run task
[2025-06-28T05:59:35.409+0000] {standard_task_runner.py:87} INFO - Running: ['airflow', 'tasks', 'run', 'films_dag_orchestaror', 'run_etl_script', 'scheduled__2025-06-28T02:55:00+00:00', '--job-id', '298', '--raw', '--subdir', 'DAGS_FOLDER/orchestrator.py', '--cfg-path', '/tmp/tmpmciprncs']
[2025-06-28T05:59:35.416+0000] {standard_task_runner.py:88} INFO - Job 298: Subtask run_etl_script
[2025-06-28T05:59:35.551+0000] {task_command.py:423} INFO - Running <TaskInstance: films_dag_orchestaror.run_etl_script scheduled__2025-06-28T02:55:00+00:00 [running]> on host 7671ab806bce
[2025-06-28T05:59:35.845+0000] {taskinstance.py:2480} INFO - Exporting env vars: AIRFLOW_CTX_DAG_OWNER='airflow' AIRFLOW_CTX_DAG_ID='films_dag_orchestaror' AIRFLOW_CTX_TASK_ID='run_etl_script' AIRFLOW_CTX_EXECUTION_DATE='2025-06-28T02:55:00+00:00' AIRFLOW_CTX_TRY_NUMBER='2' AIRFLOW_CTX_DAG_RUN_ID='scheduled__2025-06-28T02:55:00+00:00'
[2025-06-28T06:00:01.402+0000] {taskinstance.py:2698} ERROR - Task failed with exception
Traceback (most recent call last):
  File "/home/airflow/.local/lib/python3.10/site-packages/airflow/models/taskinstance.py", line 433, in _execute_task
    result = execute_callable(context=context, **execute_callable_kwargs)
  File "/home/airflow/.local/lib/python3.10/site-packages/airflow/operators/python.py", line 199, in execute
    return_value = self.execute_callable()
  File "/home/airflow/.local/lib/python3.10/site-packages/airflow/operators/python.py", line 216, in execute_callable
    return self.python_callable(*self.op_args, **self.op_kwargs)
  File "/opt/airflow/dags/orchestrator.py", line 18, in run_etl_script
    raise Exception(result.stderr)
Exception
[2025-06-28T06:00:01.476+0000] {taskinstance.py:1138} INFO - Marking task as FAILED. dag_id=films_dag_orchestaror, task_id=run_etl_script, execution_date=20250628T025500, start_date=20250628T055935, end_date=20250628T060001
[2025-06-28T06:00:01.505+0000] {standard_task_runner.py:107} ERROR - Failed to execute job 298 for task run_etl_script (; 181)
[2025-06-28T06:00:01.524+0000] {local_task_job_runner.py:234} INFO - Task exited with return code 1
[2025-06-28T06:00:01.551+0000] {taskinstance.py:3280} INFO - 0 downstream tasks scheduled from follow-on schedule check
