[2025-06-29T06:38:03.256+0000] {taskinstance.py:1956} INFO - Dependencies all met for dep_context=non-requeueable deps ti=<TaskInstance: films_dag_orchestaror.dbt_task scheduled__2025-06-29T06:37:00+00:00 [queued]>
[2025-06-29T06:38:03.264+0000] {taskinstance.py:1956} INFO - Dependencies all met for dep_context=requeueable deps ti=<TaskInstance: films_dag_orchestaror.dbt_task scheduled__2025-06-29T06:37:00+00:00 [queued]>
[2025-06-29T06:38:03.265+0000] {taskinstance.py:2170} INFO - Starting attempt 1 of 1
[2025-06-29T06:38:03.276+0000] {taskinstance.py:2191} INFO - Executing <Task(DockerOperator): dbt_task> on 2025-06-29 06:37:00+00:00
[2025-06-29T06:38:03.280+0000] {standard_task_runner.py:60} INFO - Started process 374 to run task
[2025-06-29T06:38:03.284+0000] {standard_task_runner.py:87} INFO - Running: ['airflow', 'tasks', 'run', 'films_dag_orchestaror', 'dbt_task', 'scheduled__2025-06-29T06:37:00+00:00', '--job-id', '1607', '--raw', '--subdir', 'DAGS_FOLDER/orchestrator.py', '--cfg-path', '/tmp/tmpy9ie394d']
[2025-06-29T06:38:03.286+0000] {standard_task_runner.py:88} INFO - Job 1607: Subtask dbt_task
[2025-06-29T06:38:03.337+0000] {task_command.py:423} INFO - Running <TaskInstance: films_dag_orchestaror.dbt_task scheduled__2025-06-29T06:37:00+00:00 [running]> on host c3520c5c5ff0
[2025-06-29T06:38:03.424+0000] {taskinstance.py:2480} INFO - Exporting env vars: AIRFLOW_CTX_DAG_OWNER='airflow' AIRFLOW_CTX_DAG_ID='films_dag_orchestaror' AIRFLOW_CTX_TASK_ID='dbt_task' AIRFLOW_CTX_EXECUTION_DATE='2025-06-29T06:37:00+00:00' AIRFLOW_CTX_TRY_NUMBER='1' AIRFLOW_CTX_DAG_RUN_ID='scheduled__2025-06-29T06:37:00+00:00'
[2025-06-29T06:38:03.456+0000] {docker.py:359} INFO - Starting docker container from image ghcr.io/dbt-labs/dbt-postgres:1.9.latest
[2025-06-29T06:38:03.464+0000] {docker.py:367} WARNING - Using remote engine or docker-in-docker and mounting temporary volume from host is not supported. Falling back to `mount_tmp_dir=False` mode. You can set `mount_tmp_dir` parameter to False to disable mounting and remove the warning
[2025-06-29T06:38:03.714+0000] {taskinstance.py:2698} ERROR - Task failed with exception
Traceback (most recent call last):
  File "/home/airflow/.local/lib/python3.10/site-packages/docker/api/client.py", line 265, in _raise_for_status
    response.raise_for_status()
  File "/home/airflow/.local/lib/python3.10/site-packages/requests/models.py", line 1021, in raise_for_status
    raise HTTPError(http_error_msg, response=self)
requests.exceptions.HTTPError: 400 Client Error: Bad Request for url: http+docker://localhost/v1.49/containers/create

The above exception was the direct cause of the following exception:

Traceback (most recent call last):
  File "/home/airflow/.local/lib/python3.10/site-packages/airflow/providers/docker/operators/docker.py", line 364, in _run_image
    return self._run_image_with_mounts([*self.mounts, tmp_mount], add_tmp_variable=True)
  File "/home/airflow/.local/lib/python3.10/site-packages/airflow/providers/docker/operators/docker.py", line 391, in _run_image_with_mounts
    self.container = self.cli.create_container(
  File "/home/airflow/.local/lib/python3.10/site-packages/docker/api/container.py", line 439, in create_container
    return self.create_container_from_config(config, name, platform)
  File "/home/airflow/.local/lib/python3.10/site-packages/docker/api/container.py", line 456, in create_container_from_config
    return self._result(res, True)
  File "/home/airflow/.local/lib/python3.10/site-packages/docker/api/client.py", line 271, in _result
    self._raise_for_status(response)
  File "/home/airflow/.local/lib/python3.10/site-packages/docker/api/client.py", line 267, in _raise_for_status
    raise create_api_error_from_http_exception(e) from e
  File "/home/airflow/.local/lib/python3.10/site-packages/docker/errors.py", line 39, in create_api_error_from_http_exception
    raise cls(e, response=response, explanation=explanation) from e
docker.errors.APIError: 400 Client Error for http+docker://localhost/v1.49/containers/create: Bad Request ("invalid mount config for type "bind": bind source path does not exist: /tmp/airflowtmpj6jfsakt")

During handling of the above exception, another exception occurred:

Traceback (most recent call last):
  File "/home/airflow/.local/lib/python3.10/site-packages/docker/api/client.py", line 265, in _raise_for_status
    response.raise_for_status()
  File "/home/airflow/.local/lib/python3.10/site-packages/requests/models.py", line 1021, in raise_for_status
    raise HTTPError(http_error_msg, response=self)
requests.exceptions.HTTPError: 404 Client Error: Not Found for url: http+docker://localhost/v1.49/containers/892320cf1ad48a6ad84b3c1a3f2c885ccb3a8f1e8ef05855203e42c2cd887cac/start

The above exception was the direct cause of the following exception:

Traceback (most recent call last):
  File "/home/airflow/.local/lib/python3.10/site-packages/airflow/models/taskinstance.py", line 433, in _execute_task
    result = execute_callable(context=context, **execute_callable_kwargs)
  File "/home/airflow/.local/lib/python3.10/site-packages/airflow/providers/docker/operators/docker.py", line 502, in execute
    return self._run_image()
  File "/home/airflow/.local/lib/python3.10/site-packages/airflow/providers/docker/operators/docker.py", line 373, in _run_image
    return self._run_image_with_mounts(self.mounts, add_tmp_variable=False)
  File "/home/airflow/.local/lib/python3.10/site-packages/airflow/providers/docker/operators/docker.py", line 423, in _run_image_with_mounts
    self.cli.start(self.container["Id"])
  File "/home/airflow/.local/lib/python3.10/site-packages/docker/utils/decorators.py", line 19, in wrapped
    return f(self, resource_id, *args, **kwargs)
  File "/home/airflow/.local/lib/python3.10/site-packages/docker/api/container.py", line 1135, in start
    self._raise_for_status(res)
  File "/home/airflow/.local/lib/python3.10/site-packages/docker/api/client.py", line 267, in _raise_for_status
    raise create_api_error_from_http_exception(e) from e
  File "/home/airflow/.local/lib/python3.10/site-packages/docker/errors.py", line 39, in create_api_error_from_http_exception
    raise cls(e, response=response, explanation=explanation) from e
docker.errors.NotFound: 404 Client Error for http+docker://localhost/v1.49/containers/892320cf1ad48a6ad84b3c1a3f2c885ccb3a8f1e8ef05855203e42c2cd887cac/start: Not Found ("failed to set up container networking: network my_network not found")
[2025-06-29T06:38:03.728+0000] {taskinstance.py:1138} INFO - Marking task as FAILED. dag_id=films_dag_orchestaror, task_id=dbt_task, execution_date=20250629T063700, start_date=20250629T063803, end_date=20250629T063803
[2025-06-29T06:38:03.743+0000] {standard_task_runner.py:107} ERROR - Failed to execute job 1607 for task dbt_task (404 Client Error for http+docker://localhost/v1.49/containers/892320cf1ad48a6ad84b3c1a3f2c885ccb3a8f1e8ef05855203e42c2cd887cac/start: Not Found ("failed to set up container networking: network my_network not found"); 374)
[2025-06-29T06:38:03.791+0000] {local_task_job_runner.py:234} INFO - Task exited with return code 1
[2025-06-29T06:38:03.972+0000] {taskinstance.py:3280} INFO - 0 downstream tasks scheduled from follow-on schedule check
